#VRML_SIM R2023b utf8

EXTERNPROTO "https://raw.githubusercontent.com/cyberbotics/webots/R2023b/projects/objects/backgrounds/protos/TexturedBackground.proto"
EXTERNPROTO "https://raw.githubusercontent.com/cyberbotics/webots/R2023b/projects/objects/floors/protos/Floor.proto"
EXTERNPROTO "https://raw.githubusercontent.com/cyberbotics/webots/R2023b/projects/robots/bitcraze/crazyflie/protos/Crazyflie.proto"

WorldInfo {
}
Viewpoint {
  orientation 0.015195971989103153 -0.06713196795767291 0.9976283783621216 4.700726441283036
  position -0.920138772915525 1.5329059429302696 0.29413677556755397
}
TexturedBackground {
}
Floor {
}
DEF Tumbller Robot {
  translation -1.0070143779668839 0.00010010967277959863 0.09952727152895462
  children [
    Accelerometer {
    }
    Connector {
      translation 0 0 0.07
      rotation 0 0 1 3.141592653589793
      children [
        DEF T_magnet Shape {
          appearance PBRAppearance {
            baseColor 1 0 1
          }
          geometry Box {
            size 0.08 0.08 0.01
          }
        }
      ]
      boundingObject USE T_magnet
      physics Physics {
        density 10
      }
      distanceTolerance 0.1
      axisTolerance 3
      rotationTolerance 3
    }
    Gyro {
      rotation 0 -1 0 0
    }
    GPS {
    }
    InertialUnit {
    }
    HingeJoint {
      jointParameters HingeJointParameters {
        position -5262.378495181718
        axis 0 1 0
        anchor 0 0.11 -0.06
      }
      device [
        RotationalMotor {
          name "motor_left"
          maxVelocity 100000
        }
      ]
      endPoint DEF wheel_left Solid {
        translation -7.641966353099761e-06 0.10999921637807811 -0.05996860102609814
        rotation 0.07458233154588198 0.7051309703262706 -0.7051438083879856 2.992641025043017
        children [
          DEF wheel_left Shape {
            appearance PBRAppearance {
              baseColor 0 0 0
            }
            geometry Cylinder {
              height 0.03
              radius 0.04
            }
          }
        ]
        name "solid(2)"
        boundingObject USE wheel_left
        physics Physics {
          density 10
        }
      }
    }
    HingeJoint {
      jointParameters HingeJointParameters {
        position -4532.349772010179
        axis 0 7 0
        anchor 0 -0.11 -0.06
      }
      device [
        RotationalMotor {
          name "motor_right"
          maxVelocity 1000000
        }
      ]
      endPoint DEF wheel_right Solid {
        translation -0.0001615736786258267 -0.1109654564579802 -0.05972991051212199
        rotation 0.3485775234915648 -0.6627425054308631 0.662771515389512 2.470713253503035
        children [
          DEF wheel_right Shape {
            appearance PBRAppearance {
              baseColor 0 0 0
            }
            geometry Cylinder {
              height 0.03
              radius 0.04
            }
          }
        ]
        name "solid(1)"
        boundingObject USE wheel_right
        physics Physics {
          density 10
        }
      }
    }
    DEF T_box Solid {
      translation 0 0 -0.00025269982390258017
      children [
        DEF T_box Shape {
          appearance PBRAppearance {
            baseColor 0.4 0.5 1
          }
          geometry Box {
            size 0.08 0.18 0.13
          }
        }
      ]
      boundingObject USE T_box
      physics Physics {
        density 200
        centerOfMass [
          0 0 0.03
        ]
      }
    }
  ]
  boundingObject USE T_box
  physics Physics {
    density 200
  }
  controller "Tumbller_controller"
}
Crazyflie {
  hidden linearVelocity_0 8.028132216946013e-11 -5.294861533063208e-11 8.25664720323731e-06
  hidden angularVelocity_0 3.529914913616244e-09 -5.2914558283776905e-09 -8.073543737458715e-17
  translation 0.4999999802249596 -1.6776664725249606e-09 0.014983623438232455
  rotation -1.8781151261327918e-05 2.815246760035539e-05 -0.9999999994273535 2.4062923887863482e-05
  controller "Crazyfile_controller"
  extensionSlot [
    BallJoint {
      jointParameters BallJointParameters {
        position 2.4061808228136695e-05
      }
      jointParameters2 JointParameters {
        position -1.3300233383570697
      }
      jointParameters3 JointParameters {
        position 4.101561906491
        axis 0 1 0
      }
      endPoint Solid {
        translation -0.24999990695446245 -6.014028414227934e-06 0.0025164959456277884
        rotation -4.865089813929559e-06 0.9394986566161154 0.34255258602562827 7.02260536094347e-05
        children [
          Connector {
            rotation 0 1 0 1.5707996938995747
            boundingObject Box {
              size 0.005 0.005 0.005
            }
            physics Physics {
              density 1
            }
            distanceTolerance 0.1
            axisTolerance 3
            rotationTolerance 3
          }
          DEF magnet Shape {
            appearance PBRAppearance {
              baseColor 0 1 0
            }
            geometry Box {
              size 0.005 0.005 0.005
            }
          }
        ]
        boundingObject USE magnet
        physics Physics {
          damping Damping {
            linear 0.1
            angular 0.5
          }
        }
      }
    }
  ]
}
