#VRML_SIM R2023b utf8

EXTERNPROTO "https://raw.githubusercontent.com/cyberbotics/webots/R2023b/projects/objects/backgrounds/protos/TexturedBackground.proto"
EXTERNPROTO "https://raw.githubusercontent.com/cyberbotics/webots/R2023b/projects/objects/floors/protos/Floor.proto"
EXTERNPROTO "https://raw.githubusercontent.com/cyberbotics/webots/R2023b/projects/robots/bitcraze/crazyflie/protos/Crazyflie.proto"

WorldInfo {
}
Viewpoint {
  orientation -0.17267742818154172 -0.18251840069133615 0.9679202132436772 4.327497597548098
  position 0.6465916799037149 1.6548517748287552 1.0260597001287193
}
TexturedBackground {
}
Floor {
}
DEF Tumbller Robot {
  translation -0.0022885682730946306 0.00012138814584810886 0.09822305045492065
  rotation 4.1430824148006094e-05 0.0006075741942715083 0.9999998145685255 3.141520215148782
  children [
    Connector {
      translation 0 0 0.07
      rotation 0 0 1 3.141592653589793
      children [
        DEF T_magnet Shape {
          appearance PBRAppearance {
            baseColor 1 0 1
          }
          geometry Box {
            size 0.08 0.08 0.01
          }
        }
      ]
      boundingObject USE T_magnet
      physics Physics {
        density 500
      }
      distanceTolerance 0.1
      axisTolerance 3
      rotationTolerance 3
    }
    Gyro {
      rotation 0 -1 0 -5.307179586466759e-06
    }
    GPS {
    }
    InertialUnit {
    }
    HingeJoint {
      jointParameters HingeJointParameters {
        position -5261.822290074595
        axis 0 1 0
        anchor 0 0.11 -0.06
      }
      device [
        RotationalMotor {
          name "motor_left"
          maxVelocity 100
        }
      ]
      endPoint DEF wheel_left Solid {
        translation 9.675183329818607e-07 0.10999926344825806 -0.059981018158968696
        rotation -0.1224374070903143 0.7017890069559738 -0.7017843479736127 3.385185070955961
        children [
          DEF wheel_left Shape {
            appearance PBRAppearance {
              baseColor 0 0 0
            }
            geometry Cylinder {
              height 0.03
              radius 0.04
            }
          }
        ]
        name "solid(2)"
        boundingObject USE wheel_left
        physics Physics {
        }
      }
    }
    HingeJoint {
      jointParameters HingeJointParameters {
        position -4531.793566441244
        axis 0 7 0
        anchor 0 -0.11 -0.06
      }
      device [
        RotationalMotor {
          name "motor_right"
          maxVelocity 100
        }
      ]
      endPoint DEF wheel_right Solid {
        translation -5.798443212242875e-06 -0.11096543800964156 -0.05969780115538383
        rotation 0.5595761286261045 -0.5860182097626421 0.586052228131938 2.1212265946297215
        children [
          DEF wheel_right Shape {
            appearance PBRAppearance {
              baseColor 0 0 0
            }
            geometry Cylinder {
              height 0.03
              radius 0.04
            }
          }
        ]
        name "solid(1)"
        boundingObject USE wheel_right
        physics Physics {
        }
      }
    }
    DEF T_box Solid {
      translation 0 0 -0.00025269982390258017
      children [
        DEF T_box Shape {
          appearance PBRAppearance {
            baseColor 0.4 0.5 1
          }
          geometry Box {
            size 0.08 0.18 0.13
          }
        }
      ]
      boundingObject USE T_box
      physics Physics {
      }
    }
  ]
  boundingObject USE T_box
  physics Physics {
  }
  controller "Tumbller_controller"
  linearVelocity 4.530502162155739e-06 -2.6687884629839515e-09 5.570732540028484e-08
  angularVelocity -3.4030765503588867e-09 -0.0001188229289299348 4.62512480672261e-07
}
Crazyflie {
  hidden linearVelocity_0 -2.8504611203159943e-10 1.2525176409932073e-17 -1.8077318591383164e-05
  hidden angularVelocity_0 -1.4572233429176889e-15 -3.040652107871965e-13 8.416694261824941e-17
  translation 0.49999999573413884 1.2374769664664943e-16 0.014982841540091659
  rotation -0.0008764833805292232 0.9999940427606597 -0.0033385955244145077 2.3716797418393426e-14
  controller "Crazyfile_controller"
  extensionSlot [
    BallJoint {
      jointParameters BallJointParameters {
        position -6.745361956810486e-17
      }
      jointParameters2 JointParameters {
        position -1.3300233388026323
      }
      jointParameters3 JointParameters {
        position 4.1015648494681
        axis 0 1 0
      }
      endPoint Solid {
        translation -0.24999989826592572 -1.3877787807814457e-16 0.0025172316288182527
        rotation 3.2217598067049605e-12 1 -2.4163198550287204e-12 6.892027883271305e-05
        children [
          Connector {
            rotation 0 1 0 1.5707996938995747
            boundingObject Box {
              size 0.005 0.005 0.005
            }
            physics Physics {
              density 1
            }
            distanceTolerance 0.1
            axisTolerance 3
            rotationTolerance 3
          }
          DEF magnet Shape {
            appearance PBRAppearance {
              baseColor 0 1 0
            }
            geometry Box {
              size 0.005 0.005 0.005
            }
          }
        ]
        boundingObject USE magnet
        physics Physics {
          damping Damping {
            linear 0.1
            angular 0.5
          }
        }
      }
    }
  ]
}
